<?xml version="1.0"?>
<!-- This URDF was automatically created by SolidWorks to URDF Exporter! Originally created by Stephen Brawner (brawner@gmail.com) 
     Commit Version: 1.6.0-4-g7f85cfe  Build Version: 1.6.7995.38578
     For more information, please see http://wiki.ros.org/sw_urdf_exporter -->
<robot
  name="aircraft_inspection_robot" xmlns:xacro="http://ros.org/wiki/xacro">
  
  <link name="dummy_link"></link>
  
  <link
    name="base_link">
    <inertial>
      <origin
        xyz="-0.40974645535857 0.24834344494391 0.242010590101945"
        rpy="0 0 0" />
      <mass
        value="152.3239752391313" />
      <inertia
        ixx="0.952539519630922"
        ixy="-4.26200364814785E-05"
        ixz="5.36575380324012E-05"
        iyy="3.80199276879049"
        iyz="2.4370448304257E-05"
        izz="4.07464899613958" />
    </inertial>
    <visual>
      <origin
        xyz="0 0 0"
        rpy="0 0 0" />
      <geometry>
        <mesh
          filename="package://aircraft_inspection_robot/meshes/base_link.STL" />
      </geometry>
      <material
        name="">
        <color
          rgba="0.250980392156863 0.250980392156863 0.250980392156863 1" />
      </material>
    </visual>
    <collision>
      <origin
        xyz="0 0 0"
        rpy="0 0 0" />
      <geometry>
        <mesh
          filename="package://aircraft_inspection_robot/meshes/base_link.STL" />
      </geometry>
    </collision>
  </link>

  <joint name="dummy_joint" type="fixed">
    <origin rpy="0 0 0" xyz="0 0 0" />
    <parent link="dummy_link"/>
    <child link="base_link"/>
  </joint>

  <link
    name="front_lidar_link">
    <inertial>
      <origin
        xyz="-0.00725496120108809 -0.159524101399661 -5.98196165102483E-08"
        rpy="0 0 0" />
      <mass
        value="2.62716823876827" />
      <inertia
        ixx="0.0112696941818608"
        ixy="-0.00033780129369249"
        ixz="1.4993857049244E-09"
        iyy="0.00584101301427301"
        iyz="-7.42930015937879E-09"
        izz="0.0112957202364551" />
    </inertial>
    <visual>
      <origin
        xyz="0 0 0"
        rpy="0 0 0" />
      <geometry>
        <mesh
          filename="package://aircraft_inspection_robot/meshes/front_lidar_link.STL" />
      </geometry>
      <material
        name="">
        <color
          rgba="0.792156862745098 0.819607843137255 0.933333333333333 1" />
      </material>
    </visual>
    <collision>
      <origin
        xyz="0 0 0"
        rpy="0 0 0" />
      <geometry>
        <mesh
          filename="package://aircraft_inspection_robot/meshes/front_lidar_link.STL" />
      </geometry>
    </collision>
  </link>
  <joint
    name="front_lidar_joint"
    type="fixed">
    <origin
      xyz="0.252189298222892 0.248326110601867 0.129347762825463"
      rpy="-1.57091123434865 0 0" />
    <parent
      link="base_link" />
    <child
      link="front_lidar_link" />
    <axis
      xyz="0 0 0" />
  </joint>
  <link
    name="rear_lidar_link">
    <inertial>
      <origin
        xyz="-0.00725495907227769 -0.159524101502578 -5.98195511736233E-08"
        rpy="0 0 0" />
      <mass
        value="2.62716823908889" />
      <inertia
        ixx="0.0112696941918823"
        ixy="-0.000337801221774006"
        ixz="1.49990162575632E-09"
        iyy="0.00584101300629532"
        iyz="-7.42946478333022E-09"
        izz="0.0112957202365325" />
    </inertial>
    <visual>
      <origin
        xyz="0 0 0"
        rpy="0 0 0" />
      <geometry>
        <mesh
          filename="package://aircraft_inspection_robot/meshes/rear_lidar_link.STL" />
      </geometry>
      <material
        name="">
        <color
          rgba="0.792156862745098 0.819607843137255 0.933333333333333 1" />
      </material>
    </visual>
    <collision>
      <origin
        xyz="0 0 0"
        rpy="0 0 0" />
      <geometry>
        <mesh
          filename="package://aircraft_inspection_robot/meshes/rear_lidar_link.STL" />
      </geometry>
    </collision>
  </link>
  <joint
    name="rear_lidar_joint"
    type="fixed">
    <origin
      xyz="-1.07167463581468 0.248325943235427 0.129347754093208"
      rpy="-1.57068141924114 0 3.14159265358979" />
    <parent
      link="base_link" />
    <child
      link="rear_lidar_link" />
    <axis
      xyz="0 0 0" />
  </joint>
  <link
    name="front_right_wheel_link">
    <inertial>
      <origin
        xyz="7.69611511519663E-07 -1.70468712881733E-07 0.102621158507274"
        rpy="0 0 0" />
      <mass
        value="26.0461976105726" />
      <inertia
        ixx="0.285954065616882"
        ixy="7.95282541629767E-07"
        ixz="1.27020782265502E-07"
        iyy="0.28595474175216"
        iyz="-3.78487432157488E-07"
        izz="0.40415282922357" />
    </inertial>
    <visual>
      <origin
        xyz="0 0 0"
        rpy="0 0 0" />
      <geometry>
        <mesh
          filename="package://aircraft_inspection_robot/meshes/front_right_wheel_link.STL" />
      </geometry>
      <material
        name="">
        <color
          rgba="0.792156862745098 0.819607843137255 0.933333333333333 1" />
      </material>
    </visual>
    <collision>
      <origin
        xyz="0 0 0"
        rpy="0 0 0" />
      <geometry>
        <cylinder radius="0.2281" length="0.2032"/>
        <!-- <mesh
          filename="package://aircraft_inspection_robot/meshes/front_right_wheel_link.STL" /> -->
      </geometry>
    </collision>
  </link>
  <joint
    name="front_right_wheel_joint"
    type="continuous">
    <origin
      xyz="-0.117597527933808 -0.0373680425515616 0.10160911911045"
      rpy="-1.57068160265985 -0.0571716575997457 3.14159265358979" />
    <parent
      link="base_link" />
    <child
      link="front_right_wheel_link" />
    <axis
      xyz="0 0 1" />
  </joint>
  <link
    name="front_left_wheel_link">
    <inertial>
      <origin
        xyz="1.06668829737838E-07 -1.81805510673927E-07 -0.102621158507274"
        rpy="0 0 0" />
      <mass
        value="26.0463242126014" />
      <inertia
        ixx="0.285954618303477"
        ixy="7.68759858498613E-07"
        ixz="6.28786224972317E-07"
        iyy="0.285955290913927"
        iyz="3.7011482934088E-07"
        izz="0.404153186322765" />
    </inertial>
    <visual>
      <origin
        xyz="0 0 0"
        rpy="0 0 0" />
      <geometry>
        <cylinder radius="0.2281" length="0.2032"/>
        <!-- <mesh
          filename="package://aircraft_inspection_robot/meshes/front_left_wheel_link.STL" /> -->
      </geometry>
      <material
        name="">
        <color
          rgba="0.792156862745098 0.819607843137255 0.933333333333333 1" />
      </material>
    </visual>
    <collision>
      <origin
        xyz="0 0 0"
        rpy="0 0 0" />
      <geometry>
        <cylinder radius="0.2281" length="0.2032"/>
        <!-- <mesh
          filename="package://aircraft_inspection_robot/meshes/front_left_wheel_link.STL" /> -->
      </geometry>
    </collision>
  </link>
  <joint
    name="front_left_wheel_joint"
    type="continuous">
    <origin
      xyz="-0.117597527933808 0.67 0.10160911911045"
      rpy="1.57056878031369 -1.04143176730992 0.000196477434083904" />
    <parent
      link="base_link" />
    <child
      link="front_left_wheel_link" />
    <axis
      xyz="0 0 1" />
  </joint>
  <link
    name="back_right_wheel_link">
    <inertial>
      <origin
        xyz="8.41577684762562E-08 -1.68242609732694E-07 0.102641039115083"
        rpy="0 0 0" />
      <mass
        value="26.0462008072991" />
      <inertia
        ixx="0.285954040177974"
        ixy="7.90067012358279E-07"
        ixz="-6.50671063736261E-07"
        iyy="0.285954742544619"
        iyz="-3.69738156013685E-07"
        izz="0.40415280236699" />
    </inertial>
    <visual>
      <origin
        xyz="0 0 0"
        rpy="0 0 0" />
      <geometry>
        <mesh
          filename="package://aircraft_inspection_robot/meshes/back_right_wheel_link.STL" />
      </geometry>
      <material
        name="">
        <color
          rgba="0.792156862745098 0.819607843137255 0.933333333333333 1" />
      </material>
    </visual>
    <collision>
      <origin
        xyz="0 0 0"
        rpy="0 0 0" />
      <geometry>
        <cylinder radius="0.2281" length="0.2032"/>
        <!-- <mesh
          filename="package://aircraft_inspection_robot/meshes/back_right_wheel_link.STL" /> -->
      </geometry>
    </collision>
  </link>
  <joint
    name="back_right_wheel_joint"
    type="continuous">
    <origin
      xyz="-0.701797527935311 -0.0373482051170577 0.101609112969085"
      rpy="1.57064724689163 -0.690734458596981 9.50549862212618E-05" />
    <parent
      link="base_link" />
    <child
      link="back_right_wheel_link" />
    <axis
      xyz="0 0 1" />
  </joint>
  <link
    name="back_left_wheel_link">
    <inertial>
      <origin
        xyz="1.29034836829356E-07 -2.66555836092586E-06 -0.102621158507274"
        rpy="0 0 0" />
      <mass
        value="26.0463122941313" />
      <inertia
        ixx="0.285954575528675"
        ixy="7.71478869336928E-07"
        ixz="6.45837128179966E-07"
        iyy="0.285955250948586"
        iyz="7.90647100387111E-07"
        izz="0.404153156835058" />
    </inertial>
    <visual>
      <origin
        xyz="0 0 0"
        rpy="0 0 0" />
      <geometry>
        <cylinder radius="0.2281" length="0.2032"/>
        <!-- <mesh
          filename="package://aircraft_inspection_robot/meshes/back_left_wheel_link.STL" /> -->
      </geometry>
      <material
        name="">
        <color
          rgba="0.792156862745098 0.819607843137255 0.933333333333333 1" />
      </material>
    </visual>
    <collision>
      <origin
        xyz="0 0 0"
        rpy="0 0 0" />
      <geometry>
        <cylinder radius="0.2281" length="0.2032"/>
        <!-- <mesh
          filename="package://aircraft_inspection_robot/meshes/back_left_wheel_link.STL" /> -->
      </geometry>
    </collision>
  </link>
  <joint
    name="back_left_wheel_joint"
    type="continuous">
    <origin
      xyz="-0.701797527935311 0.67 0.101609112969085"
      rpy="1.56727528936655 -1.5381898923507 0.00352290998991109" />
    <parent
      link="base_link" />
    <child
      link="back_left_wheel_link" />
    <axis
      xyz="0 0 1" />
  </joint>
  <link
    name="arm_base_link">
    <inertial>
      <origin
        xyz="-1.64295967997052E-07 0.231013183516839 0.049503043395059"
        rpy="0 0 0" />
      <mass
        value="4.94633477448353" />
      <inertia
        ixx="1.41939380135235"
        ixy="-8.90881223634171E-07"
        ixz="9.56220690256119E-07"
        iyy="1.27036787158441"
        iyz="-0.0880230019550541"
        izz="0.931256676518883" />
    </inertial>
    <visual>
      <origin
        xyz="0 0 0"
        rpy="0 0 0" />
      <geometry>
        <mesh
          filename="package://aircraft_inspection_robot/meshes/arm_base_link.STL" />
      </geometry>
      <material
        name="">
        <color
          rgba="1 1 1 1" />
      </material>
    </visual>
    <collision>
      <origin
        xyz="0 0 0"
        rpy="0 0 0" />
      <geometry>
        <mesh
          filename="package://aircraft_inspection_robot/meshes/arm_base_link.STL" />
      </geometry>
    </collision>
  </link>
  <joint
    name="arm_base_joint"
    type="continuous">
    <origin
      xyz="-0.409742672306299 0.248387046108564 0.660376290839812"
      rpy="1.57079632680359 0.000114907553872355 1.57079640245869" />
    <parent
      link="base_link" />
    <child
      link="arm_base_link" />
    <axis
      xyz="0 1 0" />
  </joint>
  <link
    name="arm_link_1">
    <inertial>
      <origin
        xyz="-0.0372792279944005 0.426695142555641 -0.479484473911662"
        rpy="0 0 0" />
      <mass
        value="0.45531535202482" />
      <inertia
        ixx="5.83147761609791"
        ixy="0.464362340696364"
        ixz="0.0181479436428272"
        iyy="0.557025555450064"
        iyz="-0.207714622846255"
        izz="5.66378782226248" />
    </inertial>
    <visual>
      <origin
        xyz="0 0 0"
        rpy="0 0 0" />
      <geometry>
        <mesh
          filename="package://aircraft_inspection_robot/meshes/arm_link_1.STL" />
      </geometry>
      <material
        name="">
        <color
          rgba="1 1 1 1" />
      </material>
    </visual>
    <collision>
      <origin
        xyz="0 0 0"
        rpy="0 0 0" />
      <geometry>
        <mesh
          filename="package://aircraft_inspection_robot/meshes/arm_link_1.STL" />
      </geometry>
    </collision>
  </link>
  <joint
    name="arm_link_1_joint"
    type="continuous">
    <origin
      xyz="0 0.266699994442256 -0.0254000017630377"
      rpy="-3.14159264700432 0 -3.05444635463409" />
    <parent
      link="arm_base_link" />
    <child
      link="arm_link_1" />
    <axis
      xyz="0 0 -1" />
  </joint>
  <link
    name="arm_link_2">
    <inertial>
      <origin
        xyz="-0.0372794216662831 -0.426695125634995 0.155515526088335"
        rpy="0 0 0" />
      <mass
        value="0.455315352024768" />
      <inertia
        ixx="5.83147818820347"
        ixy="-0.464359091558048"
        ixz="0.0181471140196324"
        iyy="0.557024983344353"
        iyz="0.207714695328513"
        izz="5.66378782226227" />
    </inertial>
    <visual>
      <origin
        xyz="0 0 0"
        rpy="0 0 0" />
      <geometry>
        <mesh
          filename="package://aircraft_inspection_robot/meshes/arm_link_2.STL" />
      </geometry>
      <material
        name="">
        <color
          rgba="1 1 1 1" />
      </material>
    </visual>
    <collision>
      <origin
        xyz="0 0 0"
        rpy="0 0 0" />
      <geometry>
        <mesh
          filename="package://aircraft_inspection_robot/meshes/arm_link_2.STL" />
      </geometry>
    </collision>
  </link>
  <joint
    name="arm_link_2_joint"
    type="continuous">
    <origin
      xyz="-0.069638 0.79706 0"
      rpy="-3.1416 0 0" />
    <parent
      link="arm_link_1" />
    <child
      link="arm_link_2" />
    <axis
      xyz="0 0 -1" />
  </joint>
  <link
    name="arm_link_3">
    <inertial>
      <origin
        xyz="-0.0196317798013794 -0.224705189100464 0.497191005211974"
        rpy="0 0 0" />
      <mass
        value="0.317053240308613" />
      <inertia
        ixx="1.87953235728557"
        ixy="-0.138313038122859"
        ixz="0.00672807661397747"
        iyy="0.308500360870789"
        iyz="0.0770053740505552"
        izz="1.82187288938407" />
    </inertial>
    <visual>
      <origin
        xyz="0 0 0"
        rpy="0 0 0" />
      <geometry>
        <mesh
          filename="package://aircraft_inspection_robot/meshes/arm_link_3.STL" />
      </geometry>
      <material
        name="">
        <color
          rgba="1 1 1 1" />
      </material>
    </visual>
    <collision>
      <origin
        xyz="0 0 0"
        rpy="0 0 0" />
      <geometry>
        <mesh
          filename="package://aircraft_inspection_robot/meshes/arm_link_3.STL" />
      </geometry>
    </collision>
  </link>
  <joint
    name="arm_link_3_joint"
    type="continuous">
    <origin
      xyz="-0.069638 -0.79706 0"
      rpy="0 0 0" />
    <parent
      link="arm_link_2" />
    <child
      link="arm_link_3" />
    <axis
      xyz="0 0 1" />
  </joint>
  <link
    name="arm_link_4">
    <inertial>
      <origin
        xyz="-0.00225991388917834 -9.44354448390028E-07 -0.686443635379313"
        rpy="0 0 0" />
      <mass
        value="0.291827459543752" />
      <inertia
        ixx="1.43479094583571"
        ixy="-6.99548069272076E-09"
        ixz="-0.0156260344498578"
        iyy="1.44213765403444"
        iyz="-7.5715520551036E-08"
        izz="0.224051315592854" />
    </inertial>
    <visual>
      <origin
        xyz="0 0 0"
        rpy="0 0 0" />
      <geometry>
        <mesh
          filename="package://aircraft_inspection_robot/meshes/arm_link_4.STL" />
      </geometry>
      <material
        name="">
        <color
          rgba="1 1 1 1" />
      </material>
    </visual>
    <collision>
      <origin
        xyz="0 0 0"
        rpy="0 0 0" />
      <geometry>
        <mesh
          filename="package://aircraft_inspection_robot/meshes/arm_link_4.STL" />
      </geometry>
    </collision>
  </link>
  <joint
    name="arm_link_4_joint"
    type="continuous">
    <origin
      xyz="-0.021323 -0.24407 0.508"
      rpy="-3.0713 -1.5708 1.4134" />
    <parent
      link="arm_link_3" />
    <child
      link="arm_link_4" />
    <axis
      xyz="0 0 -1" />
  </joint>
  <link
    name="arm_link_5">
    <inertial>
      <origin
        xyz="6.43929354282591E-15 -4.44089209850063E-16 0.583424416047374"
        rpy="0 0 0" />
      <mass
        value="0.41227054564651" />
      <inertia
        ixx="1.92995623100548"
        ixy="0.0650573018555175"
        ixz="-2.96700504282669E-14"
        iyy="2.66891181079381"
        iyz="4.23062739418566E-16"
        izz="1.53738026195758" />
    </inertial>
    <visual>
      <origin
        xyz="0 0 0"
        rpy="0 0 0" />
      <geometry>
        <mesh
          filename="package://aircraft_inspection_robot/meshes/arm_link_5.STL" />
      </geometry>
      <material
        name="">
        <color
          rgba="0.250980392156863 0.250980392156863 0.250980392156863 1" />
      </material>
    </visual>
    <collision>
      <origin
        xyz="0 0 0"
        rpy="0 0 0" />
      <geometry>
        <mesh
          filename="package://aircraft_inspection_robot/meshes/arm_link_5.STL" />
      </geometry>
    </collision>
  </link>
  <joint
    name="arm_link_5_joint"
    type="continuous">
    <origin
      xyz="-0.127 0 -0.9234"
      rpy="1.5708 -0.087146 1.5708" />
    <parent
      link="arm_link_4" />
    <child
      link="arm_link_5" />
    <axis
      xyz="0 0 1" />
  </joint>
  <link
    name="camera_link">
    <inertial>
      <origin
        xyz="1.2060623173473 0.138272316836035 -0.00419630171526747"
        rpy="0 0 0" />
      <mass
        value="0.676402187018761" />
      <inertia
        ixx="7.05925773573284"
        ixy="0.00160005295963165"
        ixz="0.0222511113797514"
        iyy="7.10657034997836"
        iyz="0.000413253450750154"
        izz="0.724964091144847" />
    </inertial>
    <visual>
      <origin
        xyz="0 0 0"
        rpy="0 0 0" />
      <geometry>
        <mesh
          filename="package://aircraft_inspection_robot/meshes/camera_link.STL" />
      </geometry>
      <material
        name="">
        <color
          rgba="0.792156862745098 0.819607843137255 0.933333333333333 1" />
      </material>
    </visual>
    <collision>
      <origin
        xyz="0 0 0"
        rpy="0 0 0" />
      <geometry>
        <mesh
          filename="package://aircraft_inspection_robot/meshes/camera_link.STL" />
      </geometry>
    </collision>
  </link>
  <joint
    name="camera_link_joint"
    type="fixed">
    <origin
      xyz="0.0121589249497853 0.139169858407754 -0.3556"
      rpy="3.05444641868214 -1.57079625379441 0" />
    <parent
      link="arm_link_5" />
    <child
      link="camera_link" />
    <axis
      xyz="0 1 0" />
  </joint>

  <!-- <gazebo>
    <plugin name="object_controller" filename="libgazebo_ros_planar_move.so">
      <ros>
        <argument>odom:=odom/unfiltered</argument>
      </ros>
      <command_topic>cmd_vel</command_topic>
      <odometry_topic>odom/unfiltered</odometry_topic>
      <odometry_frame>odom</odometry_frame>
      <odometry_rate>20.0</odometry_rate>
      <robot_base_frame>dummy_link</robot_base_frame>
      <publish_odom>true</publish_odom>
      <publish_odom_tf>true</publish_odom_tf>
    </plugin>
  </gazebo> -->

  <!-- <gazebo reference="front_right_wheel_link">
    <material>Gazebo/Black</material>
    <mu1 value="0.001"/>
    <mu2 value="0.001"/>
  </gazebo>

  <gazebo reference="front_left_wheel_link">
    <material>Gazebo/Black</material>
    <mu1 value="0.001"/>
    <mu2 value="0.001"/>
  </gazebo>

  <gazebo reference="back_right_wheel_link">
    <material>Gazebo/Black</material>
    <mu1 value="0.001"/>
    <mu2 value="0.001"/>
  </gazebo>

  <gazebo reference="back_left_wheel_link">
    <material>Gazebo/Black</material>
    <mu1 value="0.001"/>
    <mu2 value="0.001"/>
  </gazebo> -->

  <!-- ROS Gazebo controls -->
  <ros2_control name="GazeboSystem" type="system">
    <hardware>
        <plugin>gazebo_ros2_control/GazeboSystem</plugin>
    </hardware>

    <!-- Velocity controllers -->

    <!-- Front Wheels -->
    <joint name="front_right_wheel_joint">
        <command_interface name="velocity">
            <param name="min">-1000.0</param>
            <param name="max">1000.0</param>
        </command_interface>
        <state_interface name="position"/>
        <state_interface name="velocity"/>
    </joint>

    <joint name="front_left_wheel_joint">
        <command_interface name="velocity">
            <param name="min">-1000.0</param>
            <param name="max">1000.0</param>
        </command_interface>
        <state_interface name="position"/>
        <state_interface name="velocity"/>
    </joint>

    <joint name="back_right_wheel_joint">
        <command_interface name="velocity">
            <param name="min">-1000.0</param>
            <param name="max">1000.0</param>
        </command_interface>
        <state_interface name="position"/>
        <state_interface name="velocity"/>
    </joint>

    <joint name="back_left_wheel_joint">
        <command_interface name="velocity">
            <param name="min">-1000.0</param>
            <param name="max">1000.0</param>
        </command_interface>
        <state_interface name="position"/>
        <state_interface name="velocity"/>
    </joint>

    <!-- Position Controllers -->
    <joint name="arm_base_joint">
        <command_interface name="position">
            <param name="min">-3.1415</param>
            <param name="max">3.1415</param>
        </command_interface>
        <state_interface name="position"/>
        <state_interface name="velocity"/>
        <!-- <command_interface name="velocity">
            <param name="min">-1000.0</param>
            <param name="max">1000.0</param>
        </command_interface>
        <state_interface name="position"/>
        <state_interface name="velocity"/> -->
    </joint>

    <joint name="arm_link_1_joint">
        <command_interface name="position">
            <param name="min">-1.57</param>
            <param name="max">1.57</param>
        </command_interface>
        <state_interface name="position"/>
        <state_interface name="velocity"/>
        <!-- <command_interface name="velocity">
            <param name="min">-1000.0</param>
            <param name="max">1000.0</param>
        </command_interface>
        <state_interface name="position"/>
        <state_interface name="velocity"/> -->
    </joint>

    <joint name="arm_link_2_joint">
        <command_interface name="position">
            <param name="min">-1.57</param>
            <param name="max">1.57</param>
        </command_interface>
        <state_interface name="position"/>
        <state_interface name="velocity"/>
        <!-- <command_interface name="velocity">
            <param name="min">-1000.0</param>
            <param name="max">1000.0</param>
        </command_interface>
        <state_interface name="position"/>
        <state_interface name="velocity"/> -->
    </joint>

    <joint name="arm_link_3_joint">
        <command_interface name="position">
            <param name="min">-1.57</param>
            <param name="max">1.57</param>
        </command_interface>
        <state_interface name="position"/>
        <state_interface name="velocity"/>
        <!-- <command_interface name="velocity">
            <param name="min">-1000.0</param>
            <param name="max">1000.0</param>
        </command_interface>
        <state_interface name="position"/>
        <state_interface name="velocity"/> -->
    </joint>

    <joint name="arm_link_4_joint">
        <command_interface name="position">
            <param name="min">-1.57</param>
            <param name="max">1.57</param>
        </command_interface>
        <state_interface name="position"/>
        <state_interface name="velocity"/>
        <!-- <command_interface name="velocity">
            <param name="min">-1000.0</param>
            <param name="max">1000.0</param>
        </command_interface>
        <state_interface name="position"/>
        <state_interface name="velocity"/> -->
    </joint>

    <joint name="arm_link_5_joint">
        <command_interface name="position">
            <param name="min">-3.1415</param>
            <param name="max">3.1415</param>
        </command_interface>
        <state_interface name="position"/>
        <state_interface name="velocity"/>
        <!-- <command_interface name="velocity">
            <param name="min">-1000.0</param>
            <param name="max">1000.0</param>
        </command_interface>
        <state_interface name="position"/>
        <state_interface name="velocity"/> -->
    </joint>
    
  </ros2_control>

  <!-- Sensors -->
  
  <!-- Front LiDAR -->
  <link name="front_lidar_sensor_link"></link>
  <joint name="front_lidar_sensor_joint" type="fixed">
    <origin rpy="1.571 1.571 0" xyz="0 -0.1 0" />
    <parent link="front_lidar_link"/>
    <child link="front_lidar_sensor_link"/>
  </joint>
  <gazebo reference="front_lidar_sensor_link">
    <sensor name="front_lidar" type="ray">
      <pose>0.0 0.0 0.0 0 0 0</pose>
      <always_on>true</always_on>
      <visualize>false</visualize>
      <update_rate>5</update_rate>
      <ray>
        <scan>
          <horizontal>
            <samples>360</samples>
            <resolution>1.00000</resolution>
            <min_angle>-0.2</min_angle>
            <max_angle>3.2</max_angle>
          </horizontal>
        </scan>
        <range>
          <min>0.4</min>
          <max>20.0</max>
          <resolution>0.015000</resolution>
        </range>
        <noise>
          <type>gaussian</type>
          <mean>0.0</mean>
          <stddev>0.01</stddev>
        </noise>
      </ray>
      <plugin name="front_scan" filename="libgazebo_ros_ray_sensor.so">
        <ros>
          <remapping>~/out:=front_scan</remapping>
        </ros>
        <output_type>sensor_msgs/LaserScan</output_type>
        <frame_name>front_lidar_sensor_link</frame_name>
      </plugin>
    </sensor>
  </gazebo>

  <!-- Rear LiDAR -->
  <link name="rear_lidar_sensor_link"></link>
  <joint name="rear_lidar_sensor_joint" type="fixed">
    <origin rpy="1.571 1.571 0" xyz="0.0 -0.1 0" />
    <parent link="rear_lidar_link"/>
    <child link="rear_lidar_sensor_link"/>
  </joint>
  <gazebo reference="rear_lidar_sensor_link">
    <sensor name="rear_lidar" type="ray">
      <pose>0.0 0.0 0.0 0 0 0</pose>
      <always_on>true</always_on>
      <visualize>false</visualize>
      <update_rate>5</update_rate>
      <ray>
        <scan>
          <horizontal>
            <samples>360</samples>
            <resolution>1.00000</resolution>
            <min_angle>-0.2</min_angle>
            <max_angle>3.4</max_angle>
          </horizontal>
        </scan>
        <range>
          <min>0.4</min>
          <max>20.0</max>
          <resolution>0.015000</resolution>
        </range>
        <noise>
          <type>gaussian</type>
          <mean>0.0</mean>
          <stddev>0.01</stddev>
        </noise>
      </ray>
      <plugin name="rear_scan" filename="libgazebo_ros_ray_sensor.so">
        <ros>
          <remapping>~/out:=rear_scan</remapping>
        </ros>
        <output_type>sensor_msgs/LaserScan</output_type>
        <frame_name>rear_lidar_sensor_link</frame_name>
      </plugin>
    </sensor>
  </gazebo>

  <!-- Depth Camera -->
  <link name="depth_camera_sensor_link"></link>
  <joint name="depth_camera_sensor_joint" type="fixed">
    <origin rpy="-1.571 0 0" xyz="1.3 0 0" />
    <parent link="camera_link"/>
    <child link="depth_camera_sensor_link"/>
  </joint>
  <gazebo reference="depth_camera_sensor_link">
    <sensor name="depth_camera" type="depth">
      <camera name="depth_camera">
        <!-- Camera properties -->
        <horizontal_fov>1.047</horizontal_fov>
        <vertical_fov>0.785</vertical_fov>
        <image>
          <width>640</width>
          <height>480</height>
        </image>
        <clip>
          <near>0.1</near>
          <far>20.0</far>
        </clip>
      </camera>

      <!-- Depth camera Gazebo plugin -->
      <plugin name="gazebo_ros_depth_camera" filename="libgazebo_ros_camera.so">
        <alwaysOn>true</alwaysOn>
        <updateRate>30.0</updateRate>
        <cameraName>depth</cameraName>
        <frameName>depth_camera_sensor_link</frameName>
        <imageTopicName>image_raw</imageTopicName>
        <cameraInfoTopicName>camera_info</cameraInfoTopicName>
      </plugin>
    </sensor>
  </gazebo>

  <gazebo>
    <plugin filename="libgazebo_ros2_control.so" name="gazebo_ros2_control">
        <parameters>$(find aircraft_inspection_robot)/config/control.yaml</parameters>
    </plugin>
  </gazebo>

</robot>