<?xml version="1.0" encoding="utf-8"?>
<!-- This URDF was automatically created by SolidWorks to URDF Exporter! Originally created by Stephen Brawner (brawner@gmail.com) 
     Commit Version: 1.6.0-4-g7f85cfe  Build Version: 1.6.7995.38578
     For more information, please see http://wiki.ros.org/sw_urdf_exporter -->
<robot
  name="new_car_assembly_export">
  <link
    name="base_link">
    <inertial>
      <origin
        xyz="0.0984933879187387 0.0524164095634679 0.139538868480493"
        rpy="0 0 0" />
      <mass
        value="42.437819295697" />
      <inertia
        ixx="0.793248965062798"
        ixy="-0.0438841068170687"
        ixz="0.12082958397428"
        iyy="2.9050823428007"
        iyz="0.00250976744462378"
        izz="3.47432493664263" />
    </inertial>
    <visual>
      <origin
        xyz="0 0 0"
        rpy="0 0 0" />
      <geometry>
        <mesh
          filename="package://new_car_assembly_export/meshes/base_link.STL" />
      </geometry>
      <material
        name="">
        <color
          rgba="1 1 1 1" />
      </material>
    </visual>
    <collision>
      <origin
        xyz="0 0 0"
        rpy="0 0 0" />
      <geometry>
        <mesh
          filename="package://new_car_assembly_export/meshes/base_link.STL" />
      </geometry>
    </collision>
  </link>
  <link
    name="back_left_wheel_link">
    <inertial>
      <origin
        xyz="2.20710116849432E-11 2.36282771126639E-10 0.0494452643769656"
        rpy="0 0 0" />
      <mass
        value="0.92951595082452" />
      <inertia
        ixx="0.00334561969767302"
        ixy="-1.35440590458226E-12"
        ixz="-4.94375218117616E-13"
        iyy="0.00334561968353542"
        iyz="-5.13247204339626E-12"
        izz="0.00569925253419484" />
    </inertial>
    <visual>
      <origin
        xyz="0 0 0"
        rpy="0 0 0" />
      <geometry>
        <mesh
          filename="package://new_car_assembly_export/meshes/back_left_wheel_link.STL" />
      </geometry>
      <material
        name="">
        <color
          rgba="0.250980392156863 0.250980392156863 0.250980392156863 1" />
      </material>
    </visual>
    <collision>
      <origin
        xyz="0 0 0"
        rpy="0 0 0" />
      <geometry>
        <mesh
          filename="package://new_car_assembly_export/meshes/back_left_wheel_link.STL" />
      </geometry>
    </collision>
  </link>
  <joint
    name="back_left_wheel_joint"
    type="continuous">
    <origin
      xyz="0.328921249974496 -0.114964083839878 -0.0177944693206667"
      rpy="-1.5707963267949 0.469083696110007 -3.12082450627461" />
    <parent
      link="base_link" />
    <child
      link="back_left_wheel_link" />
    <axis
      xyz="0 0 1" />
  </joint>
  <link
    name="back_right_wheel_link">
    <inertial>
      <origin
        xyz="2.20231055614306E-11 2.37201022712519E-10 0.049028557176643"
        rpy="0 0 0" />
      <mass
        value="0.929515950065346" />
      <inertia
        ixx="0.00334561969632988"
        ixy="-1.3558820863918E-12"
        ixz="-4.94323406806298E-13"
        iyy="0.0033456196821762"
        iyz="-5.15615432565997E-12"
        izz="0.00569925253212831" />
    </inertial>
    <visual>
      <origin
        xyz="0 0 0"
        rpy="0 0 0" />
      <geometry>
        <mesh
          filename="package://new_car_assembly_export/meshes/back_right_wheel_link.STL" />
      </geometry>
      <material
        name="">
        <color
          rgba="0.250980392156863 0.250980392156863 0.250980392156863 1" />
      </material>
    </visual>
    <collision>
      <origin
        xyz="0 0 0"
        rpy="0 0 0" />
      <geometry>
        <mesh
          filename="package://new_car_assembly_export/meshes/back_right_wheel_link.STL" />
      </geometry>
    </collision>
  </link>
  <joint
    name="back_right_wheel_joint"
    type="continuous">
    <origin
      xyz="0.32176 0.22964 -0.017794"
      rpy="1.5708 -0.29161 -3.1208" />
    <parent
      link="base_link" />
    <child
      link="back_right_wheel_link" />
    <axis
      xyz="0 0 1" />
  </joint>
  <link
    name="front_left_steer_link">
    <inertial>
      <origin
        xyz="1.66547595339406E-05 0.0339902371024883 0.00881686935201456"
        rpy="0 0 0" />
      <mass
        value="0.979289581300228" />
      <inertia
        ixx="0.00377322325335636"
        ixy="8.43295143974749E-07"
        ixz="-9.37539386378886E-07"
        iyy="0.00118944602853968"
        iyz="0.000447122954117804"
        izz="0.00324735803538192" />
    </inertial>
    <visual>
      <origin
        xyz="0 0 0"
        rpy="0 0 0" />
      <geometry>
        <mesh
          filename="package://new_car_assembly_export/meshes/front_left_steer_link.STL" />
      </geometry>
      <material
        name="">
        <color
          rgba="1 1 1 1" />
      </material>
    </visual>
    <collision>
      <origin
        xyz="0 0 0"
        rpy="0 0 0" />
      <geometry>
        <mesh
          filename="package://new_car_assembly_export/meshes/front_left_steer_link.STL" />
      </geometry>
    </collision>
  </link>
  <joint
    name="front_left_steer_joint"
    type="revolute">
    <origin
      xyz="-0.179708588418403 -0.0899166088816682 0"
      rpy="1.5707963267949 0 0.0940442461119153" />
    <parent
      link="base_link" />
    <child
      link="front_left_steer_link" />
    <axis
      xyz="0 1 0" />
    <limit
      lower="-0.785"
      upper="0.785"
      effort="100"
      velocity="3.14" />
  </joint>
  <link
    name="front_left_wheel_link">
    <inertial>
      <origin
        xyz="-2.14738671289183E-10 -1.01100960936407E-10 0.0703981423141871"
        rpy="0 0 0" />
      <mass
        value="0.929515950960186" />
      <inertia
        ixx="0.00334561968624407"
        ixy="-5.53230372669515E-12"
        ixz="4.6719790579644E-12"
        iyy="0.00334561969544727"
        iyz="2.18302884992007E-12"
        izz="0.00569925253456414" />
    </inertial>
    <visual>
      <origin
        xyz="0 0 0"
        rpy="0 0 0" />
      <geometry>
        <mesh
          filename="package://new_car_assembly_export/meshes/front_left_wheel_link.STL" />
      </geometry>
      <material
        name="">
        <color
          rgba="0.250980392156863 0.250980392156863 0.250980392156863 1" />
      </material>
    </visual>
    <collision>
      <origin
        xyz="0 0 0"
        rpy="0 0 0" />
      <geometry>
        <mesh
          filename="package://new_car_assembly_export/meshes/front_left_wheel_link.STL" />
      </geometry>
    </collision>
  </link>
  <joint
    name="front_left_wheel_joint"
    type="continuous">
    <origin
      xyz="0.000125211657348218 -0.0177944693206653 0.014651735605834"
      rpy="0 0 -2.49079241735017" />
    <parent
      link="front_left_steer_link" />
    <child
      link="front_left_wheel_link" />
    <axis
      xyz="0 0 1" />
  </joint>
  <link
    name="front_right_steer_link">
    <inertial>
      <origin
        xyz="0.000499399069158218 0.0339902366670281 0.0088027301319186"
        rpy="0 0 0" />
      <mass
        value="0.979289573985709" />
      <inertia
        ixx="0.00377154409782337"
        ixy="2.53243838631569E-05"
        ixz="-2.96825918414848E-05"
        iyy="0.00118944602905323"
        iyz="0.000446406025058732"
        izz="0.00324903714128756" />
    </inertial>
    <visual>
      <origin
        xyz="0 0 0"
        rpy="0 0 0" />
      <geometry>
        <mesh
          filename="package://new_car_assembly_export/meshes/front_right_steer_link.STL" />
      </geometry>
      <material
        name="">
        <color
          rgba="1 1 1 1" />
      </material>
    </visual>
    <collision>
      <origin
        xyz="0 0 0"
        rpy="0 0 0" />
      <geometry>
        <mesh
          filename="package://new_car_assembly_export/meshes/front_right_steer_link.STL" />
      </geometry>
    </collision>
  </link>
  <joint
    name="front_right_steer_joint"
    type="revolute">
    <origin
      xyz="-0.18538 0.18307 0"
      rpy="1.5708 0 3.1208" />
    <parent
      link="base_link" />
    <child
      link="front_right_steer_link" />
    <axis
      xyz="0 1 0" />
    <limit
      lower="-0.785"
      upper="0.785"
      effort="100"
      velocity="3.14" />
  </joint>
  <link
    name="front_right_wheel_link">
    <inertial>
      <origin
        xyz="0.00423078348638281 0.00194568340806663 0.0436154795188722"
        rpy="0 0 0" />
      <mass
        value="0.929515950960185" />
      <inertia
        ixx="0.00335144432289555"
        ixy="2.67867175629422E-06"
        ixz="0.000116909908940042"
        iyy="0.00334685157075126"
        iyz="5.37653893864981E-05"
        izz="0.00569219602260868" />
    </inertial>
    <visual>
      <origin
        xyz="0 0 0"
        rpy="0 0 0" />
      <geometry>
        <mesh
          filename="package://new_car_assembly_export/meshes/front_right_wheel_link.STL" />
      </geometry>
      <material
        name="">
        <color
          rgba="0.250980392156863 0.250980392156863 0.250980392156863 1" />
      </material>
    </visual>
    <collision>
      <origin
        xyz="0 0 0"
        rpy="0 0 0" />
      <geometry>
        <mesh
          filename="package://new_car_assembly_export/meshes/front_right_wheel_link.STL" />
      </geometry>
    </collision>
  </link>
  <joint
    name="front_right_wheel_joint"
    type="continuous">
    <origin
      xyz="0.000125211657348301 -0.0177944693206666 0.0412999511488255"
      rpy="0 0 -0.431045729807837" />
    <parent
      link="front_right_steer_link" />
    <child
      link="front_right_wheel_link" />
    <axis
      xyz="0 0 1" />
  </joint>
</robot>