<?xml version="1.0" encoding="utf-8"?>
<!-- This URDF was automatically created by SolidWorks to URDF Exporter! Originally created by Stephen Brawner (brawner@gmail.com) 
     Commit Version: 1.6.0-4-g7f85cfe  Build Version: 1.6.7995.38578
     For more information, please see http://wiki.ros.org/sw_urdf_exporter -->
<robot
  name="new_car_assembly_export">
  <link
    name="base_link">
    <inertial>
      <origin
        xyz="0.0984933879187388 0.0524164095634679 0.139538868480493"
        rpy="0 0 0" />
      <mass
        value="42.437819295697" />
      <inertia
        ixx="0.793248965062798"
        ixy="-0.0438841068170687"
        ixz="0.12082958397428"
        iyy="2.9050823428007"
        iyz="0.00250976744462378"
        izz="3.47432493664263" />
    </inertial>
    <visual>
      <origin
        xyz="0 0 0"
        rpy="0 0 0" />
      <geometry>
        <mesh
          filename="package://new_car_assembly_export/meshes/base_link.STL" />
      </geometry>
      <material
        name="">
        <color
          rgba="1 1 1 1" />
      </material>
    </visual>
    <collision>
      <origin
        xyz="0 0 0"
        rpy="0 0 0" />
      <geometry>
        <mesh
          filename="package://new_car_assembly_export/meshes/base_link.STL" />
      </geometry>
    </collision>
  </link>
  <link
    name="back_left_wheel_link">
    <inertial>
      <origin
        xyz="2.20710116849432E-11 2.36282771126639E-10 0.0494452643769656"
        rpy="0 0 0" />
      <mass
        value="0.92951595082452" />
      <inertia
        ixx="0.00334561969767302"
        ixy="-1.3544059046352E-12"
        ixz="-4.94375218117616E-13"
        iyy="0.00334561968353542"
        iyz="-5.13247205017253E-12"
        izz="0.00569925253419484" />
    </inertial>
    <visual>
      <origin
        xyz="0 0 0"
        rpy="0 0 0" />
      <geometry>
        <mesh
          filename="package://new_car_assembly_export/meshes/back_left_wheel_link.STL" />
      </geometry>
      <material
        name="">
        <color
          rgba="0.250980392156863 0.250980392156863 0.250980392156863 1" />
      </material>
    </visual>
    <collision>
      <origin
        xyz="0 0 0"
        rpy="0 0 0" />
      <geometry>
        <mesh
          filename="package://new_car_assembly_export/meshes/back_left_wheel_link.STL" />
      </geometry>
    </collision>
  </link>
  <joint
    name="back_left_wheel_joint"
    type="continuous">
    <origin
      xyz="0.328921249974496 -0.114964083839878 -0.0177944693206667"
      rpy="-1.5707963267949 0.469083696110007 -3.12082450627461" />
    <parent
      link="base_link" />
    <child
      link="back_left_wheel_link" />
    <axis
      xyz="0 0 1" />
  </joint>
  <link
    name="back_right_wheel_link">
    <inertial>
      <origin
        xyz="2.20231055614306E-11 2.37201022712519E-10 0.049028557176643"
        rpy="0 0 0" />
      <mass
        value="0.929515950065346" />
      <inertia
        ixx="0.00334561969632988"
        ixy="-1.3558819778657E-12"
        ixz="-4.94323420358826E-13"
        iyy="0.0033456196821762"
        iyz="-5.15615434260063E-12"
        izz="0.00569925253212831" />
    </inertial>
    <visual>
      <origin
        xyz="0 0 0"
        rpy="0 0 0" />
      <geometry>
        <mesh
          filename="package://new_car_assembly_export/meshes/back_right_wheel_link.STL" />
      </geometry>
      <material
        name="">
        <color
          rgba="0.250980392156863 0.250980392156863 0.250980392156863 1" />
      </material>
    </visual>
    <collision>
      <origin
        xyz="0 0 0"
        rpy="0 0 0" />
      <geometry>
        <mesh
          filename="package://new_car_assembly_export/meshes/back_right_wheel_link.STL" />
      </geometry>
    </collision>
  </link>
  <joint
    name="back_right_wheel_joint"
    type="continuous">
    <origin
      xyz="0.321763483964631 0.229637520986015 -0.0177944693206667"
      rpy="1.5707963267949 -0.291614530450468 -3.12082450627461" />
    <parent
      link="base_link" />
    <child
      link="back_right_wheel_link" />
    <axis
      xyz="0 0 1" />
  </joint>
  <link
    name="front_left_steer_link">
    <inertial>
      <origin
        xyz="1.66547595339128E-05 0.0339902371024883 0.00881686935201453"
        rpy="0 0 0" />
      <mass
        value="0.979289581300228" />
      <inertia
        ixx="0.00377322325335636"
        ixy="8.43295143974749E-07"
        ixz="-9.37539386378859E-07"
        iyy="0.00118944602853968"
        iyz="0.000447122954117804"
        izz="0.00324735803538192" />
    </inertial>
    <visual>
      <origin
        xyz="0 0 0"
        rpy="0 0 0" />
      <geometry>
        <mesh
          filename="package://new_car_assembly_export/meshes/front_left_steer_link.STL" />
      </geometry>
      <material
        name="">
        <color
          rgba="1 1 1 1" />
      </material>
    </visual>
    <collision>
      <origin
        xyz="0 0 0"
        rpy="0 0 0" />
      <geometry>
        <mesh
          filename="package://new_car_assembly_export/meshes/front_left_steer_link.STL" />
      </geometry>
    </collision>
  </link>
  <joint
    name="front_left_steer_joint"
    type="revolute">
    <origin
      xyz="-0.17971 -0.089917 0"
      rpy="1.5708 0 0.094044" />
    <parent
      link="base_link" />
    <child
      link="front_left_steer_link" />
    <axis
      xyz="0 1 0" />
    <limit
      lower="-0.785"
      upper="0.785"
      effort="100"
      velocity="3.14" />
  </joint>
  <link
    name="front_left_wheel_link">
    <inertial>
      <origin
        xyz="-2.14738699044759E-10 -1.01100947058619E-10 0.0703981423141871"
        rpy="0 0 0" />
      <mass
        value="0.929515950960186" />
      <inertia
        ixx="0.00334561968624407"
        ixy="-5.5323038334213E-12"
        ixz="4.6719790579644E-12"
        iyy="0.00334561969544726"
        iyz="2.1830288634726E-12"
        izz="0.00569925253456414" />
    </inertial>
    <visual>
      <origin
        xyz="0 0 0"
        rpy="0 0 0" />
      <geometry>
        <mesh
          filename="package://new_car_assembly_export/meshes/front_left_wheel_link.STL" />
      </geometry>
      <material
        name="">
        <color
          rgba="0.250980392156863 0.250980392156863 0.250980392156863 1" />
      </material>
    </visual>
    <collision>
      <origin
        xyz="0 0 0"
        rpy="0 0 0" />
      <geometry>
        <mesh
          filename="package://new_car_assembly_export/meshes/front_left_wheel_link.STL" />
      </geometry>
    </collision>
  </link>
  <joint
    name="front_left_wheel_joint"
    type="continuous">
    <origin
      xyz="0.000125211657348218 -0.0177944693206653 0.014651735605834"
      rpy="0 0 -2.49079241735017" />
    <parent
      link="front_left_steer_link" />
    <child
      link="front_left_wheel_link" />
    <axis
      xyz="0 0 1" />
  </joint>
  <link
    name="front_right_steer_link">
    <inertial>
      <origin
        xyz="0.00126307247469412 0.0339902372861786 0.00872594484877132"
        rpy="0 0 0" />
      <mass
        value="0.9792895843257" />
      <inertia
        ixx="0.00376244872178771"
        ixy="6.40518802839026E-05"
        ixz="-7.4503324424236E-05"
        iyy="0.00118944602891897"
        iyz="0.000442512140457697"
        izz="0.003258132588816" />
    </inertial>
    <visual>
      <origin
        xyz="0 0 0"
        rpy="0 0 0" />
      <geometry>
        <mesh
          filename="package://new_car_assembly_export/meshes/front_right_steer_link.STL" />
      </geometry>
      <material
        name="">
        <color
          rgba="1 1 1 1" />
      </material>
    </visual>
    <collision>
      <origin
        xyz="0 0 0"
        rpy="0 0 0" />
      <geometry>
        <mesh
          filename="package://new_car_assembly_export/meshes/front_right_steer_link.STL" />
      </geometry>
    </collision>
  </link>
  <joint
    name="front_right_steer_joint"
    type="revolute">
    <origin
      xyz="-0.18538 0.18307 0"
      rpy="1.5708 0 3.1235" />
    <parent
      link="base_link" />
    <child
      link="front_right_steer_link" />
    <axis
      xyz="0 1 0" />
    <limit
      lower="-0.785"
      upper="0.785"
      effort="100"
      velocity="3.14" />
  </joint>
  <link
    name="front_right_wheel_link">
    <inertial>
      <origin
        xyz="0.0109238220794718 0.00502372733917364 0.042877854866294"
        rpy="0 0 0" />
      <mass
        value="0.92951595459559" />
      <inertia
        ixx="0.00338445542348172"
        ixy="1.78600464053296E-05"
        ixz="0.000299295584991618"
        iyy="0.00335383331665573"
        iyz="0.000137642239695159"
        izz="0.00565220320828645" />
    </inertial>
    <visual>
      <origin
        xyz="0 0 0"
        rpy="0 0 0" />
      <geometry>
        <mesh
          filename="package://new_car_assembly_export/meshes/front_right_wheel_link.STL" />
      </geometry>
      <material
        name="">
        <color
          rgba="0.250980392156863 0.250980392156863 0.250980392156863 1" />
      </material>
    </visual>
    <collision>
      <origin
        xyz="0 0 0"
        rpy="0 0 0" />
      <geometry>
        <mesh
          filename="package://new_car_assembly_export/meshes/front_right_wheel_link.STL" />
      </geometry>
    </collision>
  </link>
  <joint
    name="front_right_wheel_joint"
    type="continuous">
    <origin
      xyz="0.000125211657348301 -0.0177944693206666 0.0412999511488255"
      rpy="0 0 -0.431045729807837" />
    <parent
      link="front_right_steer_link" />
    <child
      link="front_right_wheel_link" />
    <axis
      xyz="0 0 1" />
  </joint>
</robot>