<?xml version="1.0" encoding="utf-8"?>
<!-- This URDF was automatically created by SolidWorks to URDF Exporter! Originally created by Stephen Brawner (brawner@gmail.com) 
     Commit Version: 1.6.0-4-g7f85cfe  Build Version: 1.6.7995.38578
     For more information, please see http://wiki.ros.org/sw_urdf_exporter -->
<robot
  name="aircraft_inspection_robot">
  <link
    name="base_link">
    <inertial>
      <origin
        xyz="-0.409737523113878 0.248339713620131 0.209639401630241"
        rpy="0 0 0" />
      <mass
        value="52.4458402259021" />
      <inertia
        ixx="1.61796946709653"
        ixy="-4.26019586297761E-05"
        ixz="5.36565329733604E-05"
        iyy="3.60901877519089"
        iyz="0.00014045219036093"
        izz="4.89191044456781" />
    </inertial>
    <visual>
      <origin
        xyz="0 0 0"
        rpy="0 0 0" />
      <geometry>
        <mesh
          filename="package://aircraft_inspection_robot/meshes/base_link.STL" />
      </geometry>
      <material
        name="">
        <color
          rgba="1 1 1 1" />
      </material>
    </visual>
    <collision>
      <origin
        xyz="0 0 0"
        rpy="0 0 0" />
      <geometry>
        <mesh
          filename="package://aircraft_inspection_robot/meshes/base_link.STL" />
      </geometry>
    </collision>
  </link>
  <link
    name="front_lidar_link">
    <inertial>
      <origin
        xyz="-0.00725498730999624 -0.159524096445023 -5.18934305249186E-08"
        rpy="0 0 0" />
      <mass
        value="21.0173459101461" />
      <inertia
        ixx="0.360630213819554"
        ixy="-0.0108096413980878"
        ixz="4.79803425565932E-08"
        iyy="0.186912416456727"
        iyz="-2.37737605206146E-07"
        izz="0.361463047566562" />
    </inertial>
    <visual>
      <origin
        xyz="0 0 0"
        rpy="0 0 0" />
      <geometry>
        <mesh
          filename="package://aircraft_inspection_robot/meshes/front_lidar_link.STL" />
      </geometry>
      <material
        name="">
        <color
          rgba="0.792156862745098 0.819607843137255 0.933333333333333 1" />
      </material>
    </visual>
    <collision>
      <origin
        xyz="0 0 0"
        rpy="0 0 0" />
      <geometry>
        <mesh
          filename="package://aircraft_inspection_robot/meshes/front_lidar_link.STL" />
      </geometry>
    </collision>
  </link>
  <joint
    name="front_lidar_joint"
    type="fixed">
    <origin
      xyz="0.308106449560569 0.248338347564378 0.236097315694741"
      rpy="-1.57091123434865 0 0" />
    <parent
      link="base_link" />
    <child
      link="front_lidar_link" />
    <axis
      xyz="0 0 0" />
  </joint>
  <link
    name="rear_lidar_link">
    <inertial>
      <origin
        xyz="1.42835301483858 -0.159524087064833 5.6730245195924E-08"
        rpy="0 0 0" />
      <mass
        value="21.0173459127111" />
      <inertia
        ixx="0.360630214140233"
        ixy="-0.0108096390967668"
        ixz="4.79968519505956E-08"
        iyy="0.18691241620145"
        iyz="-2.37742872890824E-07"
        izz="0.361463047569039" />
    </inertial>
    <visual>
      <origin
        xyz="0 0 0"
        rpy="0 0 0" />
      <geometry>
        <mesh
          filename="package://aircraft_inspection_robot/meshes/rear_lidar_link.STL" />
      </geometry>
      <material
        name="">
        <color
          rgba="0.792156862745098 0.819607843137255 0.933333333333333 1" />
      </material>
    </visual>
    <collision>
      <origin
        xyz="0 0 0"
        rpy="0 0 0" />
      <geometry>
        <mesh
          filename="package://aircraft_inspection_robot/meshes/rear_lidar_link.STL" />
      </geometry>
    </collision>
  </link>
  <joint
    name="rear_lidar_joint"
    type="fixed">
    <origin
      xyz="0.308106449560569 0.248338347564378 0.236097315694741"
      rpy="-1.57068141924114 0 3.14159265358979" />
    <parent
      link="base_link" />
    <child
      link="rear_lidar_link" />
    <axis
      xyz="0 0 0" />
  </joint>
  <link
    name="front_right_wheel_link">
    <inertial>
      <origin
        xyz="-5.59829960167235E-14 1.71109293400917E-10 0.103131389958602"
        rpy="0 0 0" />
      <mass
        value="17.0942965183764" />
      <inertia
        ixx="0.267032855143768"
        ixy="-1.12643384679206E-12"
        ixz="-5.64889032158929E-10"
        iyy="0.267032853623031"
        iyz="9.3846801464399E-12"
        izz="0.388719266107455" />
    </inertial>
    <visual>
      <origin
        xyz="0 0 0"
        rpy="0 0 0" />
      <geometry>
        <mesh
          filename="package://aircraft_inspection_robot/meshes/front_right_wheel_link.STL" />
      </geometry>
      <material
        name="">
        <color
          rgba="0.250980392156863 0.250980392156863 0.250980392156863 1" />
      </material>
    </visual>
    <collision>
      <origin
        xyz="0 0 0"
        rpy="0 0 0" />
      <geometry>
        <mesh
          filename="package://aircraft_inspection_robot/meshes/front_right_wheel_link.STL" />
      </geometry>
    </collision>
  </link>
  <joint
    name="front_right_wheel_joint"
    type="continuous">
    <origin
      xyz="-0.117597527934808 -0.0373548329643068 0.101609117592568"
      rpy="-1.57057710899586 -1.01905526588804 3.14140604048142" />
    <parent
      link="base_link" />
    <child
      link="front_right_wheel_link" />
    <axis
      xyz="0 0 1" />
  </joint>
  <link
    name="front_left_wheel_link">
    <inertial>
      <origin
        xyz="-6.06656651996884E-14 1.71113873070894E-10 -0.10313316315041"
        rpy="0 0 0" />
      <mass
        value="17.0942965183763" />
      <inertia
        ixx="0.267032855143761"
        ixy="-1.14495324383746E-12"
        ixz="5.64901635417955E-10"
        iyy="0.267032853623031"
        iyz="-9.36914437972927E-12"
        izz="0.388719266107462" />
    </inertial>
    <visual>
      <origin
        xyz="0 0 0"
        rpy="0 0 0" />
      <geometry>
        <mesh
          filename="package://aircraft_inspection_robot/meshes/front_left_wheel_link.STL" />
      </geometry>
      <material
        name="">
        <color
          rgba="0.250980392156863 0.250980392156863 0.250980392156863 1" />
      </material>
    </visual>
    <collision>
      <origin
        xyz="0 0 0"
        rpy="0 0 0" />
      <geometry>
        <mesh
          filename="package://aircraft_inspection_robot/meshes/front_left_wheel_link.STL" />
      </geometry>
    </collision>
  </link>
  <joint
    name="front_left_wheel_joint"
    type="continuous">
    <origin
      xyz="-0.117597571165592 0.533998775516627 0.101543464746798"
      rpy="1.57061905476483 -0.865579426080518 0.00013506316993608" />
    <parent
      link="base_link" />
    <child
      link="front_left_wheel_link" />
    <axis
      xyz="0 0 1" />
  </joint>
  <link
    name="back_right_wheel_link">
    <inertial>
      <origin
        xyz="-6.03961325396085E-14 1.71112679581142E-10 0.103133072201983"
        rpy="0 0 0" />
      <mass
        value="17.0942965183763" />
      <inertia
        ixx="0.267032855143761"
        ixy="-1.14615484325525E-12"
        ixz="-5.64900110911116E-10"
        iyy="0.267032853623031"
        iyz="9.36830792283539E-12"
        izz="0.388719266107461" />
    </inertial>
    <visual>
      <origin
        xyz="0 0 0"
        rpy="0 0 0" />
      <geometry>
        <mesh
          filename="package://aircraft_inspection_robot/meshes/back_right_wheel_link.STL" />
      </geometry>
      <material
        name="">
        <color
          rgba="0.250980392156863 0.250980392156863 0.250980392156863 1" />
      </material>
    </visual>
    <collision>
      <origin
        xyz="0 0 0"
        rpy="0 0 0" />
      <geometry>
        <mesh
          filename="package://aircraft_inspection_robot/meshes/back_right_wheel_link.STL" />
      </geometry>
    </collision>
  </link>
  <joint
    name="back_right_wheel_joint"
    type="continuous">
    <origin
      xyz="-0.7018 -0.037353 0.10161"
      rpy="1.5706 -0.87958 0.00013896" />
    <parent
      link="base_link" />
    <child
      link="back_right_wheel_link" />
    <axis
      xyz="0 0 1" />
  </joint>
  <link
    name="back_left_wheel_link">
    <inertial>
      <origin
        xyz="-5.65658631046517E-14 1.71111347313513E-10 -0.103131061396203"
        rpy="0 0 0" />
      <mass
        value="17.0942965183761" />
      <inertia
        ixx="0.267032855143766"
        ixy="-1.12798336645332E-12"
        ixz="5.64892007313028E-10"
        iyy="0.267032853623031"
        iyz="-9.37929468555027E-12"
        izz="0.388719266107457" />
    </inertial>
    <visual>
      <origin
        xyz="0 0 0"
        rpy="0 0 0" />
      <geometry>
        <mesh
          filename="package://aircraft_inspection_robot/meshes/back_left_wheel_link.STL" />
      </geometry>
      <material
        name="">
        <color
          rgba="0.250980392156863 0.250980392156863 0.250980392156863 1" />
      </material>
    </visual>
    <collision>
      <origin
        xyz="0 0 0"
        rpy="0 0 0" />
      <geometry>
        <mesh
          filename="package://aircraft_inspection_robot/meshes/back_left_wheel_link.STL" />
      </geometry>
    </collision>
  </link>
  <joint
    name="back_left_wheel_joint"
    type="continuous">
    <origin
      xyz="-0.7018 0.534 0.10154"
      rpy="-1.5706 -1.0375 3.1414" />
    <parent
      link="base_link" />
    <child
      link="back_left_wheel_link" />
    <axis
      xyz="0 0 1" />
  </joint>
  <link
    name="arm_connector_link">
    <inertial>
      <origin
        xyz="-1.43143330522122E-10 0.0216537321612436 1.10744746706359E-14"
        rpy="0 0 0" />
      <mass
        value="2.62877306618386" />
      <inertia
        ixx="0.0207836884851897"
        ixy="-1.25135931667707E-10"
        ixz="-2.20944162334301E-25"
        iyy="0.039713380262994"
        iyz="-2.37404276874067E-17"
        izz="0.0207836884851897" />
    </inertial>
    <visual>
      <origin
        xyz="0 0 0"
        rpy="0 0 0" />
      <geometry>
        <mesh
          filename="package://aircraft_inspection_robot/meshes/arm_connector_link.STL" />
      </geometry>
      <material
        name="">
        <color
          rgba="0.250980392156863 0.250980392156863 0.250980392156863 1" />
      </material>
    </visual>
    <collision>
      <origin
        xyz="0 0 0"
        rpy="0 0 0" />
      <geometry>
        <mesh
          filename="package://aircraft_inspection_robot/meshes/arm_connector_link.STL" />
      </geometry>
    </collision>
  </link>
  <joint
    name="arm_connect_joint"
    type="fixed">
    <origin
      xyz="-0.4097 0.24836 0.41908"
      rpy="1.5707 0 0" />
    <parent
      link="base_link" />
    <child
      link="arm_connector_link" />
    <axis
      xyz="0 0 0" />
  </joint>
  <link
    name="arm_base_link">
    <inertial>
      <origin
        xyz="8.98447982677908E-14 0.118624566442621 -7.84175280266197E-10"
        rpy="0 0 0" />
      <mass
        value="16.2102374081522" />
      <inertia
        ixx="0.278054099642839"
        ixy="-4.40146949106952E-14"
        ixz="1.13856898220502E-16"
        iyy="0.226366310502593"
        iyz="6.241749681372E-10"
        izz="0.320787148766728" />
    </inertial>
    <visual>
      <origin
        xyz="0 0 0"
        rpy="0 0 0" />
      <geometry>
        <mesh
          filename="package://aircraft_inspection_robot/meshes/arm_base_link.STL" />
      </geometry>
      <material
        name="">
        <color
          rgba="1 1 1 1" />
      </material>
    </visual>
    <collision>
      <origin
        xyz="0 0 0"
        rpy="0 0 0" />
      <geometry>
        <mesh
          filename="package://aircraft_inspection_robot/meshes/arm_base_link.STL" />
      </geometry>
    </collision>
  </link>
  <joint
    name="arm_base_joint"
    type="continuous">
    <origin
      xyz="0 0.05 0"
      rpy="3.14158142866165 1.57079625081358 3.14158142866183" />
    <parent
      link="arm_connector_link" />
    <child
      link="arm_base_link" />
    <axis
      xyz="0 1 0" />
  </joint>
  <link
    name="arm_link_1">
    <inertial>
      <origin
        xyz="-0.220104658305914 -2.01750447683113E-05 -9.56656233397357E-08"
        rpy="0 0 0" />
      <mass
        value="27.8487184691269" />
      <inertia
        ixx="0.139923261741666"
        ixy="1.06663227751021E-05"
        ixz="-1.12563617274536E-06"
        iyy="0.826397782924963"
        iyz="7.66617430666479E-07"
        izz="0.851756221048375" />
    </inertial>
    <visual>
      <origin
        xyz="0 0 0"
        rpy="0 0 0" />
      <geometry>
        <mesh
          filename="package://aircraft_inspection_robot/meshes/arm_link_1.STL" />
      </geometry>
      <material
        name="">
        <color
          rgba="1 1 1 1" />
      </material>
    </visual>
    <collision>
      <origin
        xyz="0 0 0"
        rpy="0 0 0" />
      <geometry>
        <mesh
          filename="package://aircraft_inspection_robot/meshes/arm_link_1.STL" />
      </geometry>
    </collision>
  </link>
  <joint
    name="arm_link_1_joint"
    type="revolute">
    <origin
      xyz="0 0.324649998991104 0"
      rpy="1.57079632679489 0 -1.57079632679575" />
    <parent
      link="arm_base_link" />
    <child
      link="arm_link_1" />
    <axis
      xyz="0 0 -1" />
    <limit
      lower="-1.57"
      upper="1.57"
      effort="10"
      velocity="1.57" />
  </joint>
  <link
    name="arm_link_2">
    <inertial>
      <origin
        xyz="2.60152103243039E-05 -0.294932861734393 -3.0332079903328E-09"
        rpy="0 0 0" />
      <mass
        value="22.8030311855107" />
      <inertia
        ixx="0.900616527405022"
        ixy="-8.45267067148506E-06"
        ixz="-7.18053432388173E-07"
        iyy="0.0886361778058626"
        iyz="-3.34324026396674E-08"
        izz="0.913689793523493" />
    </inertial>
    <visual>
      <origin
        xyz="0 0 0"
        rpy="0 0 0" />
      <geometry>
        <mesh
          filename="package://aircraft_inspection_robot/meshes/arm_link_2.STL" />
      </geometry>
      <material
        name="">
        <color
          rgba="1 1 1 1" />
      </material>
    </visual>
    <collision>
      <origin
        xyz="0 0 0"
        rpy="0 0 0" />
      <geometry>
        <mesh
          filename="package://aircraft_inspection_robot/meshes/arm_link_2.STL" />
      </geometry>
    </collision>
  </link>
  <joint
    name="arm_link_2_joint"
    type="revolute">
    <origin
      xyz="-0.838219700899912 -7.9889090206009E-05 0"
      rpy="3.14159265358979 0 1.57079632018433" />
    <parent
      link="arm_link_1" />
    <child
      link="arm_link_2" />
    <axis
      xyz="0 0 -1" />
    <limit
      lower="-1.57"
      upper="1.57"
      effort="10"
      velocity="1.57" />
  </joint>
  <link
    name="arm_link_3">
    <inertial>
      <origin
        xyz="-2.20070710351683E-05 0.174731082769789 1.66682822572151E-06"
        rpy="0 0 0" />
      <mass
        value="18.4583758499819" />
      <inertia
        ixx="0.343099818831356"
        ixy="-7.25600004535604E-06"
        ixz="0.00051405508417309"
        iyy="0.0799779307984141"
        iyz="-3.32763039162941E-07"
        izz="0.349697140625257" />
    </inertial>
    <visual>
      <origin
        xyz="0 0 0"
        rpy="0 0 0" />
      <geometry>
        <mesh
          filename="package://aircraft_inspection_robot/meshes/arm_link_3.STL" />
      </geometry>
      <material
        name="">
        <color
          rgba="1 1 1 1" />
      </material>
    </visual>
    <collision>
      <origin
        xyz="0 0 0"
        rpy="0 0 0" />
      <geometry>
        <mesh
          filename="package://aircraft_inspection_robot/meshes/arm_link_3.STL" />
      </geometry>
    </collision>
  </link>
  <joint
    name="arm_link_3_joint"
    type="revolute">
    <origin
      xyz="7.9883045636886E-05 -0.914380299100637 0"
      rpy="0 -0.0773013935492111 -3.14158375334952" />
    <parent
      link="arm_link_2" />
    <child
      link="arm_link_3" />
    <axis
      xyz="0 0 -1" />
    <limit
      lower="-1.57"
      upper="1.57"
      effort="10"
      velocity="1.57" />
  </joint>
  <link
    name="camera_holder_link">
    <inertial>
      <origin
        xyz="0.187251012647879 -3.9949793612104E-05 -3.02499691962055E-12"
        rpy="0 0 0" />
      <mass
        value="19.8300644910614" />
      <inertia
        ixx="1.36579729580863"
        ixy="1.08993133239915E-09"
        ixz="-1.75485236693536E-15"
        iyy="1.20092006636686"
        iyz="5.67723134426706E-08"
        izz="0.450596696746023" />
    </inertial>
    <visual>
      <origin
        xyz="0 0 0"
        rpy="0 0 0" />
      <geometry>
        <mesh
          filename="package://aircraft_inspection_robot/meshes/camera_holder_link.STL" />
      </geometry>
      <material
        name="">
        <color
          rgba="0.250980392156863 0.250980392156863 0.250980392156863 1" />
      </material>
    </visual>
    <collision>
      <origin
        xyz="0 0 0"
        rpy="0 0 0" />
      <geometry>
        <mesh
          filename="package://aircraft_inspection_robot/meshes/camera_holder_link.STL" />
      </geometry>
    </collision>
  </link>
  <joint
    name="camera_holder_joint"
    type="continuous">
    <origin
      xyz="0 0.537718005012817 0"
      rpy="-3.06429133570132 0 1.5707874531331" />
    <parent
      link="arm_link_3" />
    <child
      link="camera_holder_link" />
    <axis
      xyz="1 0 0" />
  </joint>
  <link
    name="camera_link">
    <inertial>
      <origin
        xyz="0.139262314980529 -0.00172631742244517 -0.00419621059518913"
        rpy="0 0 0" />
      <mass
        value="67.6402186866665" />
      <inertia
        ixx="7.0592577317398"
        ixy="0.00160005125590436"
        ixz="0.0222515907790156"
        iyy="7.1065703493232"
        iyz="0.00041373646645367"
        izz="0.72496409449164" />
    </inertial>
    <visual>
      <origin
        xyz="0 0 0"
        rpy="0 0 0" />
      <geometry>
        <mesh
          filename="package://aircraft_inspection_robot/meshes/camera_link.STL" />
      </geometry>
      <material
        name="">
        <color
          rgba="0.792156862745098 0.819607843137255 0.933333333333333 1" />
      </material>
    </visual>
    <collision>
      <origin
        xyz="0 0 0"
        rpy="0 0 0" />
      <geometry>
        <mesh
          filename="package://aircraft_inspection_robot/meshes/camera_link.STL" />
      </geometry>
    </collision>
  </link>
  <joint
    name="camera_joint"
    type="fixed">
    <origin
      xyz="0.152399998573742 0 0"
      rpy="0 0 0" />
    <parent
      link="camera_holder_link" />
    <child
      link="camera_link" />
    <axis
      xyz="0 0 0" />
  </joint>
</robot>