<?xml version="1.0" encoding="utf-8"?>
<!-- This URDF was automatically created by SolidWorks to URDF Exporter! Originally created by Stephen Brawner (brawner@gmail.com) 
     Commit Version: 1.6.0-4-g7f85cfe  Build Version: 1.6.7995.38578
     For more information, please see http://wiki.ros.org/sw_urdf_exporter -->
<robot
  name="car_assembly">
  <link
    name="base_link">
    <inertial>
      <origin
        xyz="0.0984933879187388 0.139538868480493 -0.0524164095634679"
        rpy="0 0 0" />
      <mass
        value="42.437819295697" />
      <inertia
        ixx="0.793248965062798"
        ixy="0.12082958397428"
        ixz="0.0438841068170688"
        iyy="3.47432493664263"
        iyz="-0.00250976744462374"
        izz="2.9050823428007" />
    </inertial>
    <visual>
      <origin
        xyz="0 0 0"
        rpy="0 0 0" />
      <geometry>
        <mesh
          filename="package://car_assembly/meshes/base_link.STL" />
      </geometry>
      <material
        name="">
        <color
          rgba="1 1 1 1" />
      </material>
    </visual>
    <collision>
      <origin
        xyz="0 0 0"
        rpy="0 0 0" />
      <geometry>
        <mesh
          filename="package://car_assembly/meshes/base_link.STL" />
      </geometry>
    </collision>
  </link>
  <link
    name="back_left_wheel_link">
    <inertial>
      <origin
        xyz="2.20701026898418E-11 2.3632068524293E-10 0.0485238176719048"
        rpy="0 0 0" />
      <mass
        value="0.929515950960187" />
      <inertia
        ixx="0.00334561969791303"
        ixy="-1.35412065084509E-12"
        ixz="-4.94448256074592E-13"
        iyy="0.00334561968377833"
        iyz="-5.13307857997287E-12"
        izz="0.00569925253456415" />
    </inertial>
    <visual>
      <origin
        xyz="0 0 0"
        rpy="0 0 0" />
      <geometry>
        <mesh
          filename="package://car_assembly/meshes/back_left_wheel_link.STL" />
      </geometry>
      <material
        name="">
        <color
          rgba="0.250980392156863 0.250980392156863 0.250980392156863 1" />
      </material>
    </visual>
    <collision>
      <origin
        xyz="0 0 0"
        rpy="0 0 0" />
      <geometry>
        <mesh
          filename="package://car_assembly/meshes/back_left_wheel_link.STL" />
      </geometry>
    </collision>
  </link>
  <joint
    name="back_left_wheel_joint"
    type="continuous">
    <origin
      xyz="0.32894 -0.11589 -0.017794"
      rpy="-1.5708 1.4356 -3.1208" />
    <parent
      link="base_link" />
    <child
      link="back_left_wheel_link" />
    <axis
      xyz="0 0 1" />
  </joint>
  <link
    name="back_right_wheel_link">
    <inertial>
      <origin
        xyz="2.19100848575238E-11 2.36971997580326E-10 0.0479937520853098"
        rpy="0 0 0" />
      <mass
        value="0.929515950263186" />
      <inertia
        ixx="0.00334561969667993"
        ixy="-1.35549519578422E-12"
        ixz="-4.91341972804708E-13"
        iyy="0.00334561968253039"
        iyz="-5.15041254599154E-12"
        izz="0.00569925253266686" />
    </inertial>
    <visual>
      <origin
        xyz="0 0 0"
        rpy="0 0 0" />
      <geometry>
        <mesh
          filename="package://car_assembly/meshes/back_right_wheel_link.STL" />
      </geometry>
      <material
        name="">
        <color
          rgba="0.250980392156863 0.250980392156863 0.250980392156863 1" />
      </material>
    </visual>
    <collision>
      <origin
        xyz="0 0 0"
        rpy="0 0 0" />
      <geometry>
        <mesh
          filename="package://car_assembly/meshes/back_right_wheel_link.STL" />
      </geometry>
    </collision>
  </link>
  <joint
    name="back_right_wheel_joint"
    type="continuous">
    <origin
      xyz="0.32174 0.23067 -0.017794"
      rpy="1.5708 0 -3.1208" />
    <parent
      link="base_link" />
    <child
      link="back_right_wheel_link" />
    <axis
      xyz="0 0 1" />
  </joint>
  <link
    name="front_left_steer_link">
    <inertial>
      <origin
        xyz="1.66541358932737E-05 0.0339902365470534 0.00881686894273455"
        rpy="0 0 0" />
      <mass
        value="0.979289571979995" />
      <inertia
        ixx="0.00377322322154386"
        ixy="8.43332889853372E-07"
        ixz="-9.37533254204548E-07"
        iyy="0.00118944602771482"
        iyz="0.000447122978840801"
        izz="0.00324735800237895" />
    </inertial>
    <visual>
      <origin
        xyz="0 0 0"
        rpy="0 0 0" />
      <geometry>
        <mesh
          filename="package://car_assembly/meshes/front_left_steer_link.STL" />
      </geometry>
      <material
        name="">
        <color
          rgba="1 1 1 1" />
      </material>
    </visual>
    <collision>
      <origin
        xyz="0 0 0"
        rpy="0 0 0" />
      <geometry>
        <mesh
          filename="package://car_assembly/meshes/front_left_steer_link.STL" />
      </geometry>
    </collision>
  </link>
  <joint
    name="front_left_steer_joint"
    type="continuous">
    <origin
      xyz="-0.17971 -0.089917 0"
      rpy="1.5708 0 0.019283" />
    <parent
      link="base_link" />
    <child
      link="front_left_steer_link" />
    <axis
      xyz="0 1 0" />
    <limit
      lower="-0.785"
      upper="0.785"
      effort="100"
      velocity="3.14" />
  </joint>
  <link
    name="front_left_wheel_link">
    <inertial>
      <origin
        xyz="2.21104939912564E-11 2.36410446774471E-10 0.0491271368458189"
        rpy="0 0 0" />
      <mass
        value="0.929515950852005" />
      <inertia
        ixx="0.00334561969772165"
        ixy="-1.3543360132468E-12"
        ixz="-4.955219516504E-13"
        iyy="0.00334561968358468"
        iyz="-5.13540815097078E-12"
        izz="0.00569925253426966" />
    </inertial>
    <visual>
      <origin
        xyz="0 0 0"
        rpy="0 0 0" />
      <geometry>
        <mesh
          filename="package://car_assembly/meshes/front_left_wheel_link.STL" />
      </geometry>
      <material
        name="">
        <color
          rgba="0.250980392156863 0.250980392156863 0.250980392156863 1" />
      </material>
    </visual>
    <collision>
      <origin
        xyz="0 0 0"
        rpy="0 0 0" />
      <geometry>
        <mesh
          filename="package://car_assembly/meshes/front_left_wheel_link.STL" />
      </geometry>
    </collision>
  </link>
  <joint
    name="front_left_wheel_joint"
    type="continuous">
    <origin
      xyz="0.00012521 -0.017794 0.035923"
      rpy="0 0 1.0465" />
    <parent
      link="front_left_steer_link" />
    <child
      link="front_left_wheel_link" />
    <axis
      xyz="0 0 1" />
  </joint>
  <link
    name="front_right_steer_link">
    <inertial>
      <origin
        xyz="1.66538436364716E-05 0.0339902362547982 0.00881686876318738"
        rpy="0 0 0" />
      <mass
        value="0.979289566987531" />
      <inertia
        ixx="0.00377322320424715"
        ixy="8.43350650471856E-07"
        ixz="-9.37529907092586E-07"
        iyy="0.00118944602573503"
        iyz="0.000447122989383998"
        izz="0.00324735798453781" />
    </inertial>
    <visual>
      <origin
        xyz="0 0 0"
        rpy="0 0 0" />
      <geometry>
        <mesh
          filename="package://car_assembly/meshes/front_right_steer_link.STL" />
      </geometry>
      <material
        name="">
        <color
          rgba="1 1 1 1" />
      </material>
    </visual>
    <collision>
      <origin
        xyz="0 0 0"
        rpy="0 0 0" />
      <geometry>
        <mesh
          filename="package://car_assembly/meshes/front_right_steer_link.STL" />
      </geometry>
    </collision>
  </link>
  <joint
    name="front_right_steer_joint"
    type="continuous">
    <origin
      xyz="-0.18538 0.18307 0"
      rpy="1.5708 0 3.1278" />
    <parent
      link="base_link" />
    <child
      link="front_right_steer_link" />
    <axis
      xyz="0 1 0" />
    <limit
      lower="-0.785"
      upper="0.785"
      effort="100"
      velocity="3.14" />
  </joint>
  <link
    name="front_right_wheel_link">
    <inertial>
      <origin
        xyz="2.26368368494434E-11 2.36441574652524E-10 0.0437602213911082"
        rpy="0 0 0" />
      <mass
        value="0.929515949350559" />
      <inertia
        ixx="0.00334561969506469"
        ixy="-1.35743100890269E-12"
        ixz="-5.07741489504847E-13"
        iyy="0.00334561968089601"
        iyz="-5.13870792197681E-12"
        izz="0.0056992525301826" />
    </inertial>
    <visual>
      <origin
        xyz="0 0 0"
        rpy="0 0 0" />
      <geometry>
        <mesh
          filename="package://car_assembly/meshes/front_right_wheel_link.STL" />
      </geometry>
      <material
        name="">
        <color
          rgba="0.250980392156863 0.250980392156863 0.250980392156863 1" />
      </material>
    </visual>
    <collision>
      <origin
        xyz="0 0 0"
        rpy="0 0 0" />
      <geometry>
        <mesh
          filename="package://car_assembly/meshes/front_right_wheel_link.STL" />
      </geometry>
    </collision>
  </link>
  <joint
    name="front_right_wheel_joint"
    type="continuous">
    <origin
      xyz="0.00012521 -0.017794 0.04129"
      rpy="0 0 -0.43105" />
    <parent
      link="front_right_steer_link" />
    <child
      link="front_right_wheel_link" />
    <axis
      xyz="0 0 1" />
  </joint>
</robot>